Workbook

Sheet Appel DE Fond
B6: SYNDICAT RESIDENCE BELLES LOGE
B7: RUE ATTABARI, QUARTIER LES PRINCESSES, CASABLANCA
B10: APPEL DE FOND DES CHARGES COMMUNES DE LA COPROPRIETE N°A10-10/26
B11: Le | C11: =TODAY()
B13: MME HIND DRIOUECH ET MR ABDELAH NACHIT
B14: Merci de trouvez ci-joint le détail de votre contribution :
B16: DESIGNATION | C16: N° DE LOT | D16: MONTANT | E16: OBSERVATION
B17: Prévisions des charges communes | C17: M02 | D17: 1800 | E17: DE OCTOBRE-2026 à DCEMBRE-2026
C18: M03 | D18: 1800 | E18: DE OCTOBRE-2026 à DCEMBRE-2026
B19: TOTAL A PAYER | C19: =SUM(D17:D18)
B20: Arrêter le présent appel de fond à la somme de : TROIS MILLE SIX CENTS DIRHAM
B22: LE REGLEMENT DOIT CE FAIRE SUR LE COMPTE BANCAIRE DE LA RESIDENCE OU BIEN UN CHEQUE ETABLIT SELON LES INFORMARTION SUIVANTES :
B23: LIBELLE DU COMPTE : SYNDICAT RESIDENCE BELLES LOGES
B24: RIB: 011 780 0000402100011545 25

Sheet Cotisation 2026
E5: Résidence LES BELLES LOGES : Situation annuelle des cotisations syndicales Année 2026 | S5: Edité le : | U5: =TODAY()
B6: Nom du copropriétaire | C6: N° de Tel | D6: Date d'aquisition | E6: Etage | F6: N° du lot | G6: 46023 | H6: 46054 | I6: 46082 | J6: 46113 | K6: 46143 | L6: 46174 | M6: 46204 | N6: 46235 | O6: 46266 | P6: 46296 | Q6: 46327 | R6: 46357 | S6: Total des cotisations payées en 2025 | T6: Reste à payer en 2026 | U6: Les arriérés 2025 | V6: Les arriérés 2024 | W6: Lien PDF Statique | X6: 📲 ENVOYER WHATSAPP (1-CLIC) | Y6: Message WhatsApp Prêt | Z6: Lien Espace Client Direct
B7: NMJ CAPITAL | C7: 0669281802 | E7: RDC | F7: Magasin N° 1 | G7: 0 | H7: 0 | I7: 0 | J7: 0 | K7: 0 | L7: 0 | M7: 0 | N7: 0 | O7: 0 | P7: 0 | Q7: 0 | R7: 0 | S7: 0 | T7: =-(1800-S7) | U7: ='Cotisation 2025'!U7 | V7: ='Cotisation 2025'!V7 | W7: =HYPERLINK("https://srbl.netlify.app/pdf/appel-M01.pdf", "📄 Voir PDF (M01)") | X7: =HYPERLINK("https://wa.me/212669281802?text=%F0%9F%8F%A2%20%2ASYNDICAT%20R%C3%89SIDENCE%20BELLES%20LOGES%2A%0A%F0%9F%93%8D%20Rue%20Attabari%2C%20Quartier%20Les%20Princesses%2C%20Casablanca%0A%0ABonjour%20%2ANMJ%20CAPITAL%2A%2C%0A%0AVeuillez%20trouver%20ci-dessous%20l%27appel%20de%20cotisations%20syndicales%20pour%20votre%20bien%20%28%2AMagasin%20N%C2%B0%201%2A%20/%20M01%29%20%3A%0A%0A%F0%9F%93%85%20%2AP%C3%A9riode%20%3A%2A%20Ann%C3%A9e%202026%0A%F0%9F%92%B0%20%2ATotal%20%C3%A0%20r%C3%A9gler%20%3A%2A%20%2A1800%20DH%2A%0A%0A%F0%9F%93%84%20%2AT%C3%A9l%C3%A9charger%20votre%20document%20officiel%20%28PDF%29%20%3A%2A%0A%F0%9F%91%89%20https%3A//srbl.netlify.app/pdf/appel-M01.pdf%0A%0A%F0%9F%8F%A6%20%2ACoordonn%C3%A9es%20bancaires%20pour%20le%20virement%20%3A%2A%0A%E2%80%A2%20%2AB%C3%A9n%C3%A9ficiaire%20%3A%2A%20SYNDICAT%20RESIDENCE%20BELLES%20LOGES%0A%E2%80%A2%20%2ABanque%20%3A%2A%20BMCE%20/%20BANK%20OF%20AFRICA%0A%E2%80%A2%20%2ARIB%20%3A%2A%20%60011%20780%200000402100011545%2025%60%0A%0A_Motif%20%3A%20M01%20-%20NMJ%20CAPITAL_%0A%0AMerci%20pour%20votre%20pr%C3%A9cieuse%20collaboration.%0A%2ALe%20Bureau%20du%20Syndic%2A", "📲 Envoyer WhatsApp Direct") | Y7: 🏢 *SYNDICAT RÉSIDENCE BELLES LOGES* 📍 Rue Attabari, Quartier Les Princesses, Casablanca Bonjour *NMJ CAPITAL*, Veuillez trouver ci-dessous l'appel de cotisations syndicales pour votre bien (*Magasin N° 1* / M01) : 📅 *Période :* Année 2026 💰 *Total à régler :* *1800 DH* 📄 *Télécharger votre document officiel (PDF) :* 👉 https://srbl.netlify.app/pdf/appel-M01.pdf 🏦 *Coordonnées bancaires pour le virement :* • *Bénéficiaire :* SYNDICAT RESIDENCE BELLES LOGES • *Banque :* BMCE / BANK OF AFRICA • *RIB :* `011 780 0000402100011545 25` _Motif : M01 - NMJ CAPITAL_ Merci pour votre précieuse collaboration. *Le Bureau du Syndic* | Z7: =HYPERLINK("https://srbl.netlify.app/?client=M01", "👤 Espace Client (M01)")
B8: HIND DRIOUECH ET MR ABDELAH NACHIT | C8: 0669791313 | D8: 45313 | F8: Magasin N° 2 | G8: 0 | H8: 0 | I8: 0 | J8: 0 | K8: 0 | L8: 0 | M8: 0 | N8: 0 | O8: 0 | P8: 0 | Q8: 0 | R8: 0 | S8: =SUM(G8:R8) | T8: =-(1800-S8) | U8: ='Cotisation 2025'!U8 | V8: ='Cotisation 2025'!V8 | W8: =HYPERLINK("https://srbl.netlify.app/pdf/appel-M02.pdf", "📄 Voir PDF (M02)") | X8: =HYPERLINK("https://wa.me/212669791313?text=%F0%9F%8F%A2%20%2ASYNDICAT%20R%C3%89SIDENCE%20BELLES%20LOGES%2A%0A%F0%9F%93%8D%20Rue%20Attabari%2C%20Quartier%20Les%20Princesses%2C%20Casablanca%0A%0ABonjour%20%2AHIND%20DRIOUECH%20ET%20MR%20ABDELAH%20NACHIT%2A%2C%0A%0AVeuillez%20trouver%20ci-dessous%20l%27appel%20de%20cotisations%20syndicales%20pour%20votre%20bien%20%28%2AMagasin%20N%C2%B0%202%2A%20/%20M02%29%20%3A%0A%0A%F0%9F%93%85%20%2AP%C3%A9riode%20%3A%2A%20Ann%C3%A9e%202026%0A%F0%9F%92%B0%20%2ATotal%20%C3%A0%20r%C3%A9gler%20%3A%2A%20%2A3150%20DH%2A%20%28dont%20arri%C3%A9r%C3%A9s%20%3A%201350%20DH%29%0A%0A%F0%9F%93%84%20%2AT%C3%A9l%C3%A9charger%20votre%20document%20officiel%20%28PDF%29%20%3A%2A%0A%F0%9F%91%89%20https%3A//srbl.netlify.app/pdf/appel-M02.pdf%0A%0A%F0%9F%8F%A6%20%2ACoordonn%C3%A9es%20bancaires%20pour%20le%20virement%20%3A%2A%0A%E2%80%A2%20%2AB%C3%A9n%C3%A9ficiaire%20%3A%2A%20SYNDICAT%20RESIDENCE%20BELLES%20LOGES%0A%E2%80%A2%20%2ABanque%20%3A%2A%20BMCE%20/%20BANK%20OF%20AFRICA%0A%E2%80%A2%20%2ARIB%20%3A%2A%20%60011%20780%200000402100011545%2025%60%0A%0A_Motif%20%3A%20M02%20-%20HIND%20DRIOUECH%20ET%20MR%20ABDELAH%20NACHIT_%0A%0AMerci%20pour%20votre%20pr%C3%A9cieuse%20collaboration.%0A%2ALe%20Bureau%20du%20Syndic%2A", "📲 Envoyer WhatsApp Direct") | Y8: 🏢 *SYNDICAT RÉSIDENCE BELLES LOGES* 📍 Rue Attabari, Quartier Les Princesses, Casablanca Bonjour *HIND DRIOUECH ET MR ABDELAH NACHIT*, Veuillez trouver ci-dessous l'appel de cotisations syndicales pour votre bien (*Magasin N° 2* / M02) : 📅 *Période :* Année 2026 💰 *Total à régler :* *3150 DH* (dont arriérés : 1350 DH) 📄 *Télécharger votre document officiel (PDF) :* 👉 https://srbl.netlify.app/pdf/appel-M02.pdf 🏦 *Coordonnées bancaires pour le virement :* • *Bénéficiaire :* SYNDICAT RESIDENCE BELLES LOGES • *Banque :* BMCE / BANK OF AFRICA • *RIB :* `011 780 0000402100011545 25` _Motif : M02 - HIND DRIOUECH ET MR ABDELAH NACHIT_ Merci pour votre précieuse collaboration. *Le Bureau du Syndic* | Z8: =HYPERLINK("https://srbl.netlify.app/?client=M02", "👤 Espace Client (M02)")
B9: HIND DRIOUECH ET MR ABDELAH NACHIT | C9: 0669791313 | D9: 45987 | F9: Magasin N° 3 | G9: 0 | H9: 0 | I9: 0 | J9: 0 | K9: 0 | L9: 0 | M9: 0 | N9: 0 | O9: 0 | P9: 0 | Q9: 0 | R9: 0 | S9: =SUM(G9:R9) | T9: =-(1800-S9) | U9: ='Cotisation 2025'!U9 | V9: ='Cotisation 2025'!V9 | W9: =HYPERLINK("https://srbl.netlify.app/pdf/appel-M03.pdf", "📄 Voir PDF (M03)") | X9: =HYPERLINK("https://wa.me/212669791313?text=%F0%9F%8F%A2%20%2ASYNDICAT%20R%C3%89SIDENCE%20BELLES%20LOGES%2A%0A%F0%9F%93%8D%20Rue%20Attabari%2C%20Quartier%20Les%20Princesses%2C%20Casablanca%0A%0ABonjour%20%2AHIND%20DRIOUECH%20ET%20MR%20ABDELAH%20NACHIT%2A%2C%0A%0AVeuillez%20trouver%20ci-dessous%20l%27appel%20de%20cotisations%20syndicales%20pour%20votre%20bien%20%28%2AMagasin%20N%C2%B0%203%2A%20/%20M03%29%20%3A%0A%0A%F0%9F%93%85%20%2AP%C3%A9riode%20%3A%2A%20Ann%C3%A9e%202026%0A%F0%9F%92%B0%20%2ATotal%20%C3%A0%20r%C3%A9gler%20%3A%2A%20%2A1800%20DH%2A%0A%0A%F0%9F%93%84%20%2AT%C3%A9l%C3%A9charger%20votre%20document%20officiel%20%28PDF%29%20%3A%2A%0A%F0%9F%91%89%20https%3A//srbl.netlify.app/pdf/appel-M03.pdf%0A%0A%F0%9F%8F%A6%20%2ACoordonn%C3%A9es%20bancaires%20pour%20le%20virement%20%3A%2A%0A%E2%80%A2%20%2AB%C3%A9n%C3%A9ficiaire%20%3A%2A%20SYNDICAT%20RESIDENCE%20BELLES%20LOGES%0A%E2%80%A2%20%2ABanque%20%3A%2A%20BMCE%20/%20BANK%20OF%20AFRICA%0A%E2%80%A2%20%2ARIB%20%3A%2A%20%60011%20780%200000402100011545%2025%60%0A%0A_Motif%20%3A%20M03%20-%20HIND%20DRIOUECH%20ET%20MR%20ABDELAH%20NACHIT_%0A%0AMerci%20pour%20votre%20pr%C3%A9cieuse%20collaboration.%0A%2ALe%20Bureau%20du%20Syndic%2A", "📲 Envoyer WhatsApp Direct") | Y9: 🏢 *SYNDICAT RÉSIDENCE BELLES LOGES* 📍 Rue Attabari, Quartier Les Princesses, Casablanca Bonjour *HIND DRIOUECH ET MR ABDELAH NACHIT*, Veuillez trouver ci-dessous l'appel de cotisations syndicales pour votre bien (*Magasin N° 3* / M03) : 📅 *Période :* Année 2026 💰 *Total à régler :* *1800 DH* 📄 *Télécharger votre document officiel (PDF) :* 👉 https://srbl.netlify.app/pdf/appel-M03.pdf 🏦 *Coordonnées bancaires pour le virement :* • *Bénéficiaire :* SYNDICAT RESIDENCE BELLES LOGES • *Banque :* BMCE / BANK OF AFRICA • *RIB :* `011 780 0000402100011545 25` _Motif : M03 - HIND DRIOUECH ET MR ABDELAH NACHIT_ Merci pour votre précieuse collaboration. *Le Bureau du Syndic* | Z9: =HYPERLINK("https://srbl.netlify.app/?client=M03", "👤 Espace Client (M03)")
B10: NMJ CAPITAL | C10: 0669281802 | F10: Magasin N° 4 | G10: 0 | H10: 0 | I10: 0 | J10: 0 | K10: 0 | L10: 0 | M10: 0 | N10: 0 | O10: 0 | P10: 0 | Q10: 0 | R10: 0 | S10: =SUM(G10:R10) | T10: =-(1800-S10) | U10: ='Cotisation 2025'!U10 | V10: ='Cotisation 2025'!V10 | W10: =HYPERLINK("https://srbl.netlify.app/pdf/appel-M04.pdf", "📄 Voir PDF (M04)") | X10: =HYPERLINK("https://wa.me/212669281802?text=%F0%9F%8F%A2%20%2ASYNDICAT%20R%C3%89SIDENCE%20BELLES%20LOGES%2A%0A%F0%9F%93%8D%20Rue%20Attabari%2C%20Quartier%20Les%20Princesses%2C%20Casablanca%0A%0ABonjour%20%2ANMJ%20CAPITAL%2A%2C%0A%0AVeuillez%20trouver%20ci-dessous%20l%27appel%20de%20cotisations%20syndicales%20pour%20votre%20bien%20%28%2AMagasin%20N%C2%B0%204%2A%20/%20M04%29%20%3A%0A%0A%F0%9F%93%85%20%2AP%C3%A9riode%20%3A%2A%20Ann%C3%A9e%202026%0A%F0%9F%92%B0%20%2ATotal%20%C3%A0%20r%C3%A9gler%20%3A%2A%20%2A1800%20DH%2A%0A%0A%F0%9F%93%84%20%2AT%C3%A9l%C3%A9charger%20votre%20document%20officiel%20%28PDF%29%20%3A%2A%0A%F0%9F%91%89%20https%3A//srbl.netlify.app/pdf/appel-M04.pdf%0A%0A%F0%9F%8F%A6%20%2ACoordonn%C3%A9es%20bancaires%20pour%20le%20virement%20%3A%2A%0A%E2%80%A2%20%2AB%C3%A9n%C3%A9ficiaire%20%3A%2A%20SYNDICAT%20RESIDENCE%20BELLES%20LOGES%0A%E2%80%A2%20%2ABanque%20%3A%2A%20BMCE%20/%20BANK%20OF%20AFRICA%0A%E2%80%A2%20%2ARIB%20%3A%2A%20%60011%20780%200000402100011545%2025%60%0A%0A_Motif%20%3A%20M04%20-%20NMJ%20CAPITAL_%0A%0AMerci%20pour%20votre%20pr%C3%A9cieuse%20collaboration.%0A%2ALe%20Bureau%20du%20Syndic%2A", "📲 Envoyer WhatsApp Direct") | Y10: 🏢 *SYNDICAT RÉSIDENCE BELLES LOGES* 📍 Rue Attabari, Quartier Les Princesses, Casablanca Bonjour *NMJ CAPITAL*, Veuillez trouver ci-dessous l'appel de cotisations syndicales pour votre bien (*Magasin N° 4* / M04) : 📅 *Période :* Année 2026 💰 *Total à régler :* *1800 DH* 📄 *Télécharger votre document officiel (PDF) :* 👉 https://srbl.netlify.app/pdf/appel-M04.pdf 🏦 *Coordonnées bancaires pour le virement :* • *Bénéficiaire :* SYNDICAT RESIDENCE BELLES LOGES • *Banque :* BMCE / BANK OF AFRICA • *RIB :* `011 780 0000402100011545 25` _Motif : M04 - NMJ CAPITAL_ Merci pour votre précieuse collaboration. *Le Bureau du Syndic* | Z10: =HYPERLINK("https://srbl.netlify.app/?client=M04", "👤 Espace Client (M04)")
B11: BENYAHYA IHSAN | C11: 0662773532 | D11: 44958 | E11: 1 | F11: Appartement N°1 | G11: 300 | H11: 300 | I11: 300 | J11: 300 | K11: 300 | L11: 300 | M11: 300 | N11: 300 | O11: 300 | P11: 0 | Q11: 0 | R11: 0 | S11: =SUM(G11:R11) | T11: =-(3600-S11) | U11: ='Cotisation 2025'!U11 | V11: ='Cotisation 2025'!V11 | W11: =HYPERLINK("https://srbl.netlify.app/pdf/appel-A10.pdf", "📄 Voir PDF (A10)") | X11: =HYPERLINK("https://wa.me/212662773532?text=%F0%9F%8F%A2%20%2ASYNDICAT%20R%C3%89SIDENCE%20BELLES%20LOGES%2A%0A%F0%9F%93%8D%20Rue%20Attabari%2C%20Quartier%20Les%20Princesses%2C%20Casablanca%0A%0ABonjour%20%2ABENYAHYA%20IHSAN%2A%2C%0A%0AVeuillez%20trouver%20ci-dessous%20l%27appel%20de%20cotisations%20syndicales%20pour%20votre%20bien%20%28%2AAppartement%20N%C2%B01%2A%20/%20A10%29%20%3A%0A%0A%F0%9F%93%85%20%2AP%C3%A9riode%20%3A%2A%20Ann%C3%A9e%202026%0A%F0%9F%92%B0%20%2ATotal%20%C3%A0%20r%C3%A9gler%20%3A%2A%20%2A3600%20DH%2A%0A%0A%F0%9F%93%84%20%2AT%C3%A9l%C3%A9charger%20votre%20document%20officiel%20%28PDF%29%20%3A%2A%0A%F0%9F%91%89%20https%3A//srbl.netlify.app/pdf/appel-A10.pdf%0A%0A%F0%9F%8F%A6%20%2ACoordonn%C3%A9es%20bancaires%20pour%20le%20virement%20%3A%2A%0A%E2%80%A2%20%2AB%C3%A9n%C3%A9ficiaire%20%3A%2A%20SYNDICAT%20RESIDENCE%20BELLES%20LOGES%0A%E2%80%A2%20%2ABanque%20%3A%2A%20BMCE%20/%20BANK%20OF%20AFRICA%0A%E2%80%A2%20%2ARIB%20%3A%2A%20%60011%20780%200000402100011545%2025%60%0A%0A_Motif%20%3A%20A10%20-%20BENYAHYA%20IHSAN_%0A%0AMerci%20pour%20votre%20pr%C3%A9cieuse%20collaboration.%0A%2ALe%20Bureau%20du%20Syndic%2A", "📲 Envoyer WhatsApp Direct") | Y11: 🏢 *SYNDICAT RÉSIDENCE BELLES LOGES* 📍 Rue Attabari, Quartier Les Princesses, Casablanca Bonjour *BENYAHYA IHSAN*, Veuillez trouver ci-dessous l'appel de cotisations syndicales pour votre bien (*Appartement N°1* / A10) : 📅 *Période :* Année 2026 💰 *Total à régler :* *3600 DH* 📄 *Télécharger votre document officiel (PDF) :* 👉 https://srbl.netlify.app/pdf/appel-A10.pdf 🏦 *Coordonnées bancaires pour le virement :* • *Bénéficiaire :* SYNDICAT RESIDENCE BELLES LOGES • *Banque :* BMCE / BANK OF AFRICA • *RIB :* `011 780 0000402100011545 25` _Motif : A10 - BENYAHYA IHSAN_ Merci pour votre précieuse collaboration. *Le Bureau du Syndic* | Z11: =HYPERLINK("https://srbl.netlify.app/?client=A10", "👤 Espace Client (A10)")
B12: GHALLAB HAKIM | C12: 0661411823 | D12: 44813 | F12: Appartement N°2 | G12: 300 | H12: 300 | I12: 300 | J12: 300 | K12: 300 | L12: 300 | M12: 300 | N12: 300 | O12: 300 | P12: 300 | Q12: 300 | R12: 300 | S12: =SUM(G12:R12) | T12: =-(3600-S12) | U12: ='Cotisation 2025'!U12 | V12: ='Cotisation 2025'!V12 | W12: =HYPERLINK("https://srbl.netlify.app/pdf/appel-A02.pdf", "📄 Voir PDF (A02)") | X12: =HYPERLINK("https://wa.me/212661411823?text=%F0%9F%8F%A2%20%2ASYNDICAT%20R%C3%89SIDENCE%20BELLES%20LOGES%2A%0A%F0%9F%93%8D%20Rue%20Attabari%2C%20Quartier%20Les%20Princesses%2C%20Casablanca%0A%0ABonjour%20%2AGHALLAB%20HAKIM%2A%2C%0A%0AVeuillez%20trouver%20ci-dessous%20l%27appel%20de%20cotisations%20syndicales%20pour%20votre%20bien%20%28%2AAppartement%20N%C2%B02%2A%20/%20A02%29%20%3A%0A%0A%F0%9F%93%85%20%2AP%C3%A9riode%20%3A%2A%20Ann%C3%A9e%202026%0A%F0%9F%92%B0%20%2ATotal%20%C3%A0%20r%C3%A9gler%20%3A%2A%20%2A3600%20DH%2A%0A%0A%F0%9F%93%84%20%2AT%C3%A9l%C3%A9charger%20votre%20document%20officiel%20%28PDF%29%20%3A%2A%0A%F0%9F%91%89%20https%3A//srbl.netlify.app/pdf/appel-A02.pdf%0A%0A%F0%9F%8F%A6%20%2ACoordonn%C3%A9es%20bancaires%20pour%20le%20virement%20%3A%2A%0A%E2%80%A2%20%2AB%C3%A9n%C3%A9ficiaire%20%3A%2A%20SYNDICAT%20RESIDENCE%20BELLES%20LOGES%0A%E2%80%A2%20%2ABanque%20%3A%2A%20BMCE%20/%20BANK%20OF%20AFRICA%0A%E2%80%A2%20%2ARIB%20%3A%2A%20%60011%20780%200000402100011545%2025%60%0A%0A_Motif%20%3A%20A02%20-%20GHALLAB%20HAKIM_%0A%0AMerci%20pour%20votre%20pr%C3%A9cieuse%20collaboration.%0A%2ALe%20Bureau%20du%20Syndic%2A", "📲 Envoyer WhatsApp Direct") | Y12: 🏢 *SYNDICAT RÉSIDENCE BELLES LOGES* 📍 Rue Attabari, Quartier Les Princesses, Casablanca Bonjour *GHALLAB HAKIM*, Veuillez trouver ci-dessous l'appel de cotisations syndicales pour votre bien (*Appartement N°2* / A02) : 📅 *Période :* Année 2026 💰 *Total à régler :* *3600 DH* 📄 *Télécharger votre document officiel (PDF) :* 👉 https://srbl.netlify.app/pdf/appel-A02.pdf 🏦 *Coordonnées bancaires pour le virement :* • *Bénéficiaire :* SYNDICAT RESIDENCE BELLES LOGES • *Banque :* BMCE / BANK OF AFRICA • *RIB :* `011 780 0000402100011545 25` _Motif : A02 - GHALLAB HAKIM_ Merci pour votre précieuse collaboration. *Le Bureau du Syndic* | Z12: =HYPERLINK("https://srbl.netlify.app/?client=A02", "👤 Espace Client (A02)")
B13: NADIL IMANE | C13: 061908 2870 | D13: 44881 | F13: Appartement N°3 | G13: 300 | H13: 300 | I13: 300 | J13: 300 | K13: 300 | L13: 300 | M13: 300 | N13: 300 | O13: 300 | P13: 300 | Q13: 300 | R13: 300 | S13: =SUM(G13:R13) | T13: =-(3600-S13) | U13: ='Cotisation 2025'!U13 | V13: ='Cotisation 2025'!V13 | W13: =HYPERLINK("https://srbl.netlify.app/pdf/appel-A03.pdf", "📄 Voir PDF (A03)") | X13: =HYPERLINK("https://wa.me/212619082870?text=%F0%9F%8F%A2%20%2ASYNDICAT%20R%C3%89SIDENCE%20BELLES%20LOGES%2A%0A%F0%9F%93%8D%20Rue%20Attabari%2C%20Quartier%20Les%20Princesses%2C%20Casablanca%0A%0ABonjour%20%2ANADIL%20IMANE%2A%2C%0A%0AVeuillez%20trouver%20ci-dessous%20l%27appel%20de%20cotisations%20syndicales%20pour%20votre%20bien%20%28%2AAppartement%20N%C2%B03%2A%20/%20A03%29%20%3A%0A%0A%F0%9F%93%85%20%2AP%C3%A9riode%20%3A%2A%20Ann%C3%A9e%202026%0A%F0%9F%92%B0%20%2ATotal%20%C3%A0%20r%C3%A9gler%20%3A%2A%20%2A3600%20DH%2A%0A%0A%F0%9F%93%84%20%2AT%C3%A9l%C3%A9charger%20votre%20document%20officiel%20%28PDF%29%20%3A%2A%0A%F0%9F%91%89%20https%3A//srbl.netlify.app/pdf/appel-A03.pdf%0A%0A%F0%9F%8F%A6%20%2ACoordonn%C3%A9es%20bancaires%20pour%20le%20virement%20%3A%2A%0A%E2%80%A2%20%2AB%C3%A9n%C3%A9ficiaire%20%3A%2A%20SYNDICAT%20RESIDENCE%20BELLES%20LOGES%0A%E2%80%A2%20%2ABanque%20%3A%2A%20BMCE%20/%20BANK%20OF%20AFRICA%0A%E2%80%A2%20%2ARIB%20%3A%2A%20%60011%20780%200000402100011545%2025%60%0A%0A_Motif%20%3A%20A03%20-%20NADIL%20IMANE_%0A%0AMerci%20pour%20votre%20pr%C3%A9cieuse%20collaboration.%0A%2ALe%20Bureau%20du%20Syndic%2A", "📲 Envoyer WhatsApp Direct") | Y13: 🏢 *SYNDICAT RÉSIDENCE BELLES LOGES* 📍 Rue Attabari, Quartier Les Princesses, Casablanca Bonjour *NADIL IMANE*, Veuillez trouver ci-dessous l'appel de cotisations syndicales pour votre bien (*Appartement N°3* / A03) : 📅 *Période :* Année 2026 💰 *Total à régler :* *3600 DH* 📄 *Télécharger votre document officiel (PDF) :* 👉 https://srbl.netlify.app/pdf/appel-A03.pdf 🏦 *Coordonnées bancaires pour le virement :* • *Bénéficiaire :* SYNDICAT RESIDENCE BELLES LOGES • *Banque :* BMCE / BANK OF AFRICA • *RIB :* `011 780 0000402100011545 25` _Motif : A03 - NADIL IMANE_ Merci pour votre précieuse collaboration. *Le Bureau du Syndic* | Z13: =HYPERLINK("https://srbl.netlify.app/?client=A03", "👤 Espace Client (A03)")
B14: INSAF BASSIL | C14: 0661377432 | D14: 44838 | F14: Appartement N°4 | G14: 300 | H14: 300 | I14: 300 | J14: 300 | K14: 300 | L14: 300 | M14: 300 | N14: 300 | O14: 300 | P14: 300 | Q14: 300 | R14: 1000 | S14: =SUM(G14:R14) | T14: =-(3600-S14) | U14: ='Cotisation 2025'!U14 | V14: ='Cotisation 2025'!V14 | W14: =HYPERLINK("https://srbl.netlify.app/pdf/appel-A04.pdf", "📄 Voir PDF (A04)") | X14: =HYPERLINK("https://wa.me/212661377432?text=%F0%9F%8F%A2%20%2ASYNDICAT%20R%C3%89SIDENCE%20BELLES%20LOGES%2A%0A%F0%9F%93%8D%20Rue%20Attabari%2C%20Quartier%20Les%20Princesses%2C%20Casablanca%0A%0ABonjour%20%2AINSAF%20BASSIL%2A%2C%0A%0AVeuillez%20trouver%20ci-dessous%20l%27appel%20de%20cotisations%20syndicales%20pour%20votre%20bien%20%28%2AAppartement%20N%C2%B04%2A%20/%20A04%29%20%3A%0A%0A%F0%9F%93%85%20%2AP%C3%A9riode%20%3A%2A%20Ann%C3%A9e%202026%0A%F0%9F%92%B0%20%2ATotal%20%C3%A0%20r%C3%A9gler%20%3A%2A%20%2A5250%20DH%2A%20%28dont%20arri%C3%A9r%C3%A9s%20%3A%201650%20DH%29%0A%0A%F0%9F%93%84%20%2AT%C3%A9l%C3%A9charger%20votre%20document%20officiel%20%28PDF%29%20%3A%2A%0A%F0%9F%91%89%20https%3A//srbl.netlify.app/pdf/appel-A04.pdf%0A%0A%F0%9F%8F%A6%20%2ACoordonn%C3%A9es%20bancaires%20pour%20le%20virement%20%3A%2A%0A%E2%80%A2%20%2AB%C3%A9n%C3%A9ficiaire%20%3A%2A%20SYNDICAT%20RESIDENCE%20BELLES%20LOGES%0A%E2%80%A2%20%2ABanque%20%3A%2A%20BMCE%20/%20BANK%20OF%20AFRICA%0A%E2%80%A2%20%2ARIB%20%3A%2A%20%60011%20780%200000402100011545%2025%60%0A%0A_Motif%20%3A%20A04%20-%20INSAF%20BASSIL_%0A%0AMerci%20pour%20votre%20pr%C3%A9cieuse%20collaboration.%0A%2ALe%20Bureau%20du%20Syndic%2A", "📲 Envoyer WhatsApp Direct") | Y14: 🏢 *SYNDICAT RÉSIDENCE BELLES LOGES* 📍 Rue Attabari, Quartier Les Princesses, Casablanca Bonjour *INSAF BASSIL*, Veuillez trouver ci-dessous l'appel de cotisations syndicales pour votre bien (*Appartement N°4* / A04) : 📅 *Période :* Année 2026 💰 *Total à régler :* *5250 DH* (dont arriérés : 1650 DH) 📄 *Télécharger votre document officiel (PDF) :* 👉 https://srbl.netlify.app/pdf/appel-A04.pdf 🏦 *Coordonnées bancaires pour le virement :* • *Bénéficiaire :* SYNDICAT RESIDENCE BELLES LOGES • *Banque :* BMCE / BANK OF AFRICA • *RIB :* `011 780 0000402100011545 25` _Motif : A04 - INSAF BASSIL_ Merci pour votre précieuse collaboration. *Le Bureau du Syndic* | Z14: =HYPERLINK("https://srbl.netlify.app/?client=A04", "👤 Espace Client (A04)")
B15: MME TORRES HIND | C15: 00447551433285 | D15: 44833 | F15: Appartement N°5 | G15: 300 | H15: 300 | I15: 300 | J15: 300 | K15: 300 | L15: 300 | M15: 0 | N15: 0 | O15: 0 | P15: 0 | Q15: 0 | R15: 0 | S15: =SUM(G15:R15) | T15: =-(3600-S15) | U15: ='Cotisation 2025'!U15 | V15: ='Cotisation 2025'!V15 | W15: =HYPERLINK("https://srbl.netlify.app/pdf/appel-A05.pdf", "📄 Voir PDF (A05)") | X15: =HYPERLINK("https://wa.me/447551433285?text=%F0%9F%8F%A2%20%2ASYNDICAT%20R%C3%89SIDENCE%20BELLES%20LOGES%2A%0A%F0%9F%93%8D%20Rue%20Attabari%2C%20Quartier%20Les%20Princesses%2C%20Casablanca%0A%0ABonjour%20%2AMME%20TORRES%20HIND%2A%2C%0A%0AVeuillez%20trouver%20ci-dessous%20l%27appel%20de%20cotisations%20syndicales%20pour%20votre%20bien%20%28%2AAppartement%20N%C2%B05%2A%20/%20A05%29%20%3A%0A%0A%F0%9F%93%85%20%2AP%C3%A9riode%20%3A%2A%20Ann%C3%A9e%202026%0A%F0%9F%92%B0%20%2ATotal%20%C3%A0%20r%C3%A9gler%20%3A%2A%20%2A3600%20DH%2A%0A%0A%F0%9F%93%84%20%2AT%C3%A9l%C3%A9charger%20votre%20document%20officiel%20%28PDF%29%20%3A%2A%0A%F0%9F%91%89%20https%3A//srbl.netlify.app/pdf/appel-A05.pdf%0A%0A%F0%9F%8F%A6%20%2ACoordonn%C3%A9es%20bancaires%20pour%20le%20virement%20%3A%2A%0A%E2%80%A2%20%2AB%C3%A9n%C3%A9ficiaire%20%3A%2A%20SYNDICAT%20RESIDENCE%20BELLES%20LOGES%0A%E2%80%A2%20%2ABanque%20%3A%2A%20BMCE%20/%20BANK%20OF%20AFRICA%0A%E2%80%A2%20%2ARIB%20%3A%2A%20%60011%20780%200000402100011545%2025%60%0A%0A_Motif%20%3A%20A05%20-%20MME%20TORRES%20HIND_%0A%0AMerci%20pour%20votre%20pr%C3%A9cieuse%20collaboration.%0A%2ALe%20Bureau%20du%20Syndic%2A", "📲 Envoyer WhatsApp Direct") | Y15: 🏢 *SYNDICAT RÉSIDENCE BELLES LOGES* 📍 Rue Attabari, Quartier Les Princesses, Casablanca Bonjour *MME TORRES HIND*, Veuillez trouver ci-dessous l'appel de cotisations syndicales pour votre bien (*Appartement N°5* / A05) : 📅 *Période :* Année 2026 💰 *Total à régler :* *3600 DH* 📄 *Télécharger votre document officiel (PDF) :* 👉 https://srbl.netlify.app/pdf/appel-A05.pdf 🏦 *Coordonnées bancaires pour le virement :* • *Bénéficiaire :* SYNDICAT RESIDENCE BELLES LOGES • *Banque :* BMCE / BANK OF AFRICA • *RIB :* `011 780 0000402100011545 25` _Motif : A05 - MME TORRES HIND_ Merci pour votre précieuse collaboration. *Le Bureau du Syndic* | Z15: =HYPERLINK("https://srbl.netlify.app/?client=A05", "👤 Espace Client (A05)")
B16: NMJ CAPITAL / BEN HADDOUCH YOUNES | C16: 0669281802 | D16: 45387 | F16: Appartement N°6 | G16: 300 | H16: 300 | I16: 300 | J16: 300 | K16: 300 | L16: 300 | M16: 300 | N16: 300 | O16: 300 | P16: 300 | Q16: 300 | R16: 300 | S16: =SUM(G16:R16) | T16: =-(3600-S16) | U16: ='Cotisation 2025'!U16 | V16: ='Cotisation 2025'!V16 | W16: =HYPERLINK("https://srbl.netlify.app/pdf/appel-A06.pdf", "📄 Voir PDF (A06)") | X16: =HYPERLINK("https://wa.me/212669281802?text=%F0%9F%8F%A2%20%2ASYNDICAT%20R%C3%89SIDENCE%20BELLES%20LOGES%2A%0A%F0%9F%93%8D%20Rue%20Attabari%2C%20Quartier%20Les%20Princesses%2C%20Casablanca%0A%0ABonjour%20%2ANMJ%20CAPITAL%20/%20BEN%20HADDOUCH%20YOUNES%2A%2C%0A%0AVeuillez%20trouver%20ci-dessous%20l%27appel%20de%20cotisations%20syndicales%20pour%20votre%20bien%20%28%2AAppartement%20N%C2%B06%2A%20/%20A06%29%20%3A%0A%0A%F0%9F%93%85%20%2AP%C3%A9riode%20%3A%2A%20Ann%C3%A9e%202026%0A%F0%9F%92%B0%20%2ATotal%20%C3%A0%20r%C3%A9gler%20%3A%2A%20%2A4800%20DH%2A%20%28dont%20arri%C3%A9r%C3%A9s%20%3A%201200%20DH%29%0A%0A%F0%9F%93%84%20%2AT%C3%A9l%C3%A9charger%20votre%20document%20officiel%20%28PDF%29%20%3A%2A%0A%F0%9F%91%89%20https%3A//srbl.netlify.app/pdf/appel-A06.pdf%0A%0A%F0%9F%8F%A6%20%2ACoordonn%C3%A9es%20bancaires%20pour%20le%20virement%20%3A%2A%0A%E2%80%A2%20%2AB%C3%A9n%C3%A9ficiaire%20%3A%2A%20SYNDICAT%20RESIDENCE%20BELLES%20LOGES%0A%E2%80%A2%20%2ABanque%20%3A%2A%20BMCE%20/%20BANK%20OF%20AFRICA%0A%E2%80%A2%20%2ARIB%20%3A%2A%20%60011%20780%200000402100011545%2025%60%0A%0A_Motif%20%3A%20A06%20-%20NMJ%20CAPITAL%20/%20BEN%20HADDOUCH%20YOUNES_%0A%0AMerci%20pour%20votre%20pr%C3%A9cieuse%20collaboration.%0A%2ALe%20Bureau%20du%20Syndic%2A", "📲 Envoyer WhatsApp Direct") | Y16: 🏢 *SYNDICAT RÉSIDENCE BELLES LOGES* 📍 Rue Attabari, Quartier Les Princesses, Casablanca Bonjour *NMJ CAPITAL / BEN HADDOUCH YOUNES*, Veuillez trouver ci-dessous l'appel de cotisations syndicales pour votre bien (*Appartement N°6* / A06) : 📅 *Période :* Année 2026 💰 *Total à régler :* *4800 DH* (dont arriérés : 1200 DH) 📄 *Télécharger votre document officiel (PDF) :* 👉 https://srbl.netlify.app/pdf/appel-A06.pdf 🏦 *Coordonnées bancaires pour le virement :* • *Bénéficiaire :* SYNDICAT RESIDENCE BELLES LOGES • *Banque :* BMCE / BANK OF AFRICA • *RIB :* `011 780 0000402100011545 25` _Motif : A06 - NMJ CAPITAL / BEN HADDOUCH YOUNES_ Merci pour votre précieuse collaboration. *Le Bureau du Syndic* | Z16: =HYPERLINK("https://srbl.netlify.app/?client=A06", "👤 Espace Client (A06)")
B17: BENYAHYA IHSAN | C17: 0662773532 | D17: 44958 | E17: 2 | F17: Appartement N°7 | G17: 300 | H17: 300 | I17: 300 | J17: 300 | K17: 300 | L17: 300 | M17: 300 | N17: 300 | O17: 300 | P17: 300 | Q17: 300 | R17: 300 | S17: =SUM(G17:R17) | T17: =-(3600-S17) | U17: ='Cotisation 2025'!U17 | V17: ='Cotisation 2025'!V17 | W17: =HYPERLINK("https://srbl.netlify.app/pdf/appel-A07.pdf", "📄 Voir PDF (A07)") | X17: =HYPERLINK("https://wa.me/212662773532?text=%F0%9F%8F%A2%20%2ASYNDICAT%20R%C3%89SIDENCE%20BELLES%20LOGES%2A%0A%F0%9F%93%8D%20Rue%20Attabari%2C%20Quartier%20Les%20Princesses%2C%20Casablanca%0A%0ABonjour%20%2ABENYAHYA%20IHSAN%2A%2C%0A%0AVeuillez%20trouver%20ci-dessous%20l%27appel%20de%20cotisations%20syndicales%20pour%20votre%20bien%20%28%2AAppartement%20N%C2%B07%2A%20/%20A07%29%20%3A%0A%0A%F0%9F%93%85%20%2AP%C3%A9riode%20%3A%2A%20Ann%C3%A9e%202026%0A%F0%9F%92%B0%20%2ATotal%20%C3%A0%20r%C3%A9gler%20%3A%2A%20%2A3600%20DH%2A%0A%0A%F0%9F%93%84%20%2AT%C3%A9l%C3%A9charger%20votre%20document%20officiel%20%28PDF%29%20%3A%2A%0A%F0%9F%91%89%20https%3A//srbl.netlify.app/pdf/appel-A07.pdf%0A%0A%F0%9F%8F%A6%20%2ACoordonn%C3%A9es%20bancaires%20pour%20le%20virement%20%3A%2A%0A%E2%80%A2%20%2AB%C3%A9n%C3%A9ficiaire%20%3A%2A%20SYNDICAT%20RESIDENCE%20BELLES%20LOGES%0A%E2%80%A2%20%2ABanque%20%3A%2A%20BMCE%20/%20BANK%20OF%20AFRICA%0A%E2%80%A2%20%2ARIB%20%3A%2A%20%60011%20780%200000402100011545%2025%60%0A%0A_Motif%20%3A%20A07%20-%20BENYAHYA%20IHSAN_%0A%0AMerci%20pour%20votre%20pr%C3%A9cieuse%20collaboration.%0A%2ALe%20Bureau%20du%20Syndic%2A", "📲 Envoyer WhatsApp Direct") | Y17: 🏢 *SYNDICAT RÉSIDENCE BELLES LOGES* 📍 Rue Attabari, Quartier Les Princesses, Casablanca Bonjour *BENYAHYA IHSAN*, Veuillez trouver ci-dessous l'appel de cotisations syndicales pour votre bien (*Appartement N°7* / A07) : 📅 *Période :* Année 2026 💰 *Total à régler :* *3600 DH* 📄 *Télécharger votre document officiel (PDF) :* 👉 https://srbl.netlify.app/pdf/appel-A07.pdf 🏦 *Coordonnées bancaires pour le virement :* • *Bénéficiaire :* SYNDICAT RESIDENCE BELLES LOGES • *Banque :* BMCE / BANK OF AFRICA • *RIB :* `011 780 0000402100011545 25` _Motif : A07 - BENYAHYA IHSAN_ Merci pour votre précieuse collaboration. *Le Bureau du Syndic* | Z17: =HYPERLINK("https://srbl.netlify.app/?client=A07", "👤 Espace Client (A07)")
A18: Q | B18: MR LAHBABI NIZAR (COR | C18: 0661286870 | D18: 44813 | F18: Appartement N°8 | G18: 300 | H18: 300 | I18: 300 | J18: 300 | K18: 300 | L18: 300 | M18: 300 | N18: 300 | O18: 300 | P18: 300 | Q18: 300 | R18: 300 | S18: =SUM(G18:R18) | T18: =-(3600-S18) | U18: ='Cotisation 2025'!U18 | V18: ='Cotisation 2025'!V18 | W18: =HYPERLINK("https://srbl.netlify.app/pdf/appel-A08.pdf", "📄 Voir PDF (A08)") | X18: =HYPERLINK("https://wa.me/212661286870?text=%F0%9F%8F%A2%20%2ASYNDICAT%20R%C3%89SIDENCE%20BELLES%20LOGES%2A%0A%F0%9F%93%8D%20Rue%20Attabari%2C%20Quartier%20Les%20Princesses%2C%20Casablanca%0A%0ABonjour%20%2AMR%20LAHBABI%20NIZAR%20%28COR%2A%2C%0A%0AVeuillez%20trouver%20ci-dessous%20l%27appel%20de%20cotisations%20syndicales%20pour%20votre%20bien%20%28%2AAppartement%20N%C2%B08%2A%20/%20A08%29%20%3A%0A%0A%F0%9F%93%85%20%2AP%C3%A9riode%20%3A%2A%20Ann%C3%A9e%202026%0A%F0%9F%92%B0%20%2ATotal%20%C3%A0%20r%C3%A9gler%20%3A%2A%20%2A3600%20DH%2A%0A%0A%F0%9F%93%84%20%2AT%C3%A9l%C3%A9charger%20votre%20document%20officiel%20%28PDF%29%20%3A%2A%0A%F0%9F%91%89%20https%3A//srbl.netlify.app/pdf/appel-A08.pdf%0A%0A%F0%9F%8F%A6%20%2ACoordonn%C3%A9es%20bancaires%20pour%20le%20virement%20%3A%2A%0A%E2%80%A2%20%2AB%C3%A9n%C3%A9ficiaire%20%3A%2A%20SYNDICAT%20RESIDENCE%20BELLES%20LOGES%0A%E2%80%A2%20%2ABanque%20%3A%2A%20BMCE%20/%20BANK%20OF%20AFRICA%0A%E2%80%A2%20%2ARIB%20%3A%2A%20%60011%20780%200000402100011545%2025%60%0A%0A_Motif%20%3A%20A08%20-%20MR%20LAHBABI%20NIZAR%20%28COR_%0A%0AMerci%20pour%20votre%20pr%C3%A9cieuse%20collaboration.%0A%2ALe%20Bureau%20du%20Syndic%2A", "📲 Envoyer WhatsApp Direct") | Y18: 🏢 *SYNDICAT RÉSIDENCE BELLES LOGES* 📍 Rue Attabari, Quartier Les Princesses, Casablanca Bonjour *MR LAHBABI NIZAR (COR*, Veuillez trouver ci-dessous l'appel de cotisations syndicales pour votre bien (*Appartement N°8* / A08) : 📅 *Période :* Année 2026 💰 *Total à régler :* *3600 DH* 📄 *Télécharger votre document officiel (PDF) :* 👉 https://srbl.netlify.app/pdf/appel-A08.pdf 🏦 *Coordonnées bancaires pour le virement :* • *Bénéficiaire :* SYNDICAT RESIDENCE BELLES LOGES • *Banque :* BMCE / BANK OF AFRICA • *RIB :* `011 780 0000402100011545 25` _Motif : A08 - MR LAHBABI NIZAR (COR_ Merci pour votre précieuse collaboration. *Le Bureau du Syndic* | Z18: =HYPERLINK("https://srbl.netlify.app/?client=A08", "👤 Espace Client (A08)")
B19: ASRAGUIS ABDELGHANI | C19: 0661936094 | D19: 44896 | F19: Appartement N°9 | G19: 300 | H19: 300 | I19: 300 | J19: 300 | K19: 300 | L19: 300 | M19: 300 | N19: 300 | O19: 300 | P19: 300 | Q19: 300 | R19: 300 | S19: =SUM(G19:R19) | T19: =-(3600-S19) | U19: ='Cotisation 2025'!U19 | V19: ='Cotisation 2025'!V19 | W19: =HYPERLINK("https://srbl.netlify.app/pdf/appel-A09.pdf", "📄 Voir PDF (A09)") | X19: =HYPERLINK("https://wa.me/212661936094?text=%F0%9F%8F%A2%20%2ASYNDICAT%20R%C3%89SIDENCE%20BELLES%20LOGES%2A%0A%F0%9F%93%8D%20Rue%20Attabari%2C%20Quartier%20Les%20Princesses%2C%20Casablanca%0A%0ABonjour%20%2AASRAGUIS%20ABDELGHANI%2A%2C%0A%0AVeuillez%20trouver%20ci-dessous%20l%27appel%20de%20cotisations%20syndicales%20pour%20votre%20bien%20%28%2AAppartement%20N%C2%B09%2A%20/%20A09%29%20%3A%0A%0A%F0%9F%93%85%20%2AP%C3%A9riode%20%3A%2A%20Ann%C3%A9e%202026%0A%F0%9F%92%B0%20%2ATotal%20%C3%A0%20r%C3%A9gler%20%3A%2A%20%2A3600%20DH%2A%0A%0A%F0%9F%93%84%20%2AT%C3%A9l%C3%A9charger%20votre%20document%20officiel%20%28PDF%29%20%3A%2A%0A%F0%9F%91%89%20https%3A//srbl.netlify.app/pdf/appel-A09.pdf%0A%0A%F0%9F%8F%A6%20%2ACoordonn%C3%A9es%20bancaires%20pour%20le%20virement%20%3A%2A%0A%E2%80%A2%20%2AB%C3%A9n%C3%A9ficiaire%20%3A%2A%20SYNDICAT%20RESIDENCE%20BELLES%20LOGES%0A%E2%80%A2%20%2ABanque%20%3A%2A%20BMCE%20/%20BANK%20OF%20AFRICA%0A%E2%80%A2%20%2ARIB%20%3A%2A%20%60011%20780%200000402100011545%2025%60%0A%0A_Motif%20%3A%20A09%20-%20ASRAGUIS%20ABDELGHANI_%0A%0AMerci%20pour%20votre%20pr%C3%A9cieuse%20collaboration.%0A%2ALe%20Bureau%20du%20Syndic%2A", "📲 Envoyer WhatsApp Direct") | Y19: 🏢 *SYNDICAT RÉSIDENCE BELLES LOGES* 📍 Rue Attabari, Quartier Les Princesses, Casablanca Bonjour *ASRAGUIS ABDELGHANI*, Veuillez trouver ci-dessous l'appel de cotisations syndicales pour votre bien (*Appartement N°9* / A09) : 📅 *Période :* Année 2026 💰 *Total à régler :* *3600 DH* 📄 *Télécharger votre document officiel (PDF) :* 👉 https://srbl.netlify.app/pdf/appel-A09.pdf 🏦 *Coordonnées bancaires pour le virement :* • *Bénéficiaire :* SYNDICAT RESIDENCE BELLES LOGES • *Banque :* BMCE / BANK OF AFRICA • *RIB :* `011 780 0000402100011545 25` _Motif : A09 - ASRAGUIS ABDELGHANI_ Merci pour votre précieuse collaboration. *Le Bureau du Syndic* | Z19: =HYPERLINK("https://srbl.netlify.app/?client=A09", "👤 Espace Client (A09)")
B20: GHALLAB MOUHSSINE | C20: 0661157305 | D20: 44958 | F20: Appartement N°10 | G20: 300 | H20: 300 | I20: 300 | J20: 300 | K20: 300 | L20: 300 | M20: 300 | N20: 300 | O20: 300 | P20: 0 | Q20: 0 | R20: 0 | S20: =SUM(G20:R20) | T20: =-(3600-S20) | U20: ='Cotisation 2025'!U20 | V20: ='Cotisation 2025'!V20 | W20: =HYPERLINK("https://srbl.netlify.app/pdf/appel-A10.pdf", "📄 Voir PDF (A10)") | X20: =HYPERLINK("https://wa.me/212661157305?text=%F0%9F%8F%A2%20%2ASYNDICAT%20R%C3%89SIDENCE%20BELLES%20LOGES%2A%0A%F0%9F%93%8D%20Rue%20Attabari%2C%20Quartier%20Les%20Princesses%2C%20Casablanca%0A%0ABonjour%20%2AGHALLAB%20MOUHSSINE%2A%2C%0A%0AVeuillez%20trouver%20ci-dessous%20l%27appel%20de%20cotisations%20syndicales%20pour%20votre%20bien%20%28%2AAppartement%20N%C2%B010%2A%20/%20A10%29%20%3A%0A%0A%F0%9F%93%85%20%2AP%C3%A9riode%20%3A%2A%20Ann%C3%A9e%202026%0A%F0%9F%92%B0%20%2ATotal%20%C3%A0%20r%C3%A9gler%20%3A%2A%20%2A3600%20DH%2A%0A%0A%F0%9F%93%84%20%2AT%C3%A9l%C3%A9charger%20votre%20document%20officiel%20%28PDF%29%20%3A%2A%0A%F0%9F%91%89%20https%3A//srbl.netlify.app/pdf/appel-A10.pdf%0A%0A%F0%9F%8F%A6%20%2ACoordonn%C3%A9es%20bancaires%20pour%20le%20virement%20%3A%2A%0A%E2%80%A2%20%2AB%C3%A9n%C3%A9ficiaire%20%3A%2A%20SYNDICAT%20RESIDENCE%20BELLES%20LOGES%0A%E2%80%A2%20%2ABanque%20%3A%2A%20BMCE%20/%20BANK%20OF%20AFRICA%0A%E2%80%A2%20%2ARIB%20%3A%2A%20%60011%20780%200000402100011545%2025%60%0A%0A_Motif%20%3A%20A10%20-%20GHALLAB%20MOUHSSINE_%0A%0AMerci%20pour%20votre%20pr%C3%A9cieuse%20collaboration.%0A%2ALe%20Bureau%20du%20Syndic%2A", "📲 Envoyer WhatsApp Direct") | Y20: 🏢 *SYNDICAT RÉSIDENCE BELLES LOGES* 📍 Rue Attabari, Quartier Les Princesses, Casablanca Bonjour *GHALLAB MOUHSSINE*, Veuillez trouver ci-dessous l'appel de cotisations syndicales pour votre bien (*Appartement N°10* / A10) : 📅 *Période :* Année 2026 💰 *Total à régler :* *3600 DH* 📄 *Télécharger votre document officiel (PDF) :* 👉 https://srbl.netlify.app/pdf/appel-A10.pdf 🏦 *Coordonnées bancaires pour le virement :* • *Bénéficiaire :* SYNDICAT RESIDENCE BELLES LOGES • *Banque :* BMCE / BANK OF AFRICA • *RIB :* `011 780 0000402100011545 25` _Motif : A10 - GHALLAB MOUHSSINE_ Merci pour votre précieuse collaboration. *Le Bureau du Syndic* | Z20: =HYPERLINK("https://srbl.netlify.app/?client=A10", "👤 Espace Client (A10)")
B21: MME TORRES HIND | C21: 00447551433285 | D21: 44833 | F21: Appartement N°11 | G21: 300 | H21: 300 | I21: 300 | J21: 300 | K21: 300 | L21: 300 | M21: 0 | N21: 0 | O21: 0 | P21: 0 | Q21: 0 | R21: 0 | S21: =SUM(G21:R21) | T21: =-(3600-S21) | U21: ='Cotisation 2025'!U21 | V21: ='Cotisation 2025'!V21 | W21: =HYPERLINK("https://srbl.netlify.app/pdf/appel-A11.pdf", "📄 Voir PDF (A11)") | X21: =HYPERLINK("https://wa.me/447551433285?text=%F0%9F%8F%A2%20%2ASYNDICAT%20R%C3%89SIDENCE%20BELLES%20LOGES%2A%0A%F0%9F%93%8D%20Rue%20Attabari%2C%20Quartier%20Les%20Princesses%2C%20Casablanca%0A%0ABonjour%20%2AMME%20TORRES%20HIND%2A%2C%0A%0AVeuillez%20trouver%20ci-dessous%20l%27appel%20de%20cotisations%20syndicales%20pour%20votre%20bien%20%28%2AAppartement%20N%C2%B011%2A%20/%20A11%29%20%3A%0A%0A%F0%9F%93%85%20%2AP%C3%A9riode%20%3A%2A%20Ann%C3%A9e%202026%0A%F0%9F%92%B0%20%2ATotal%20%C3%A0%20r%C3%A9gler%20%3A%2A%20%2A3600%20DH%2A%0A%0A%F0%9F%93%84%20%2AT%C3%A9l%C3%A9charger%20votre%20document%20officiel%20%28PDF%29%20%3A%2A%0A%F0%9F%91%89%20https%3A//srbl.netlify.app/pdf/appel-A11.pdf%0A%0A%F0%9F%8F%A6%20%2ACoordonn%C3%A9es%20bancaires%20pour%20le%20virement%20%3A%2A%0A%E2%80%A2%20%2AB%C3%A9n%C3%A9ficiaire%20%3A%2A%20SYNDICAT%20RESIDENCE%20BELLES%20LOGES%0A%E2%80%A2%20%2ABanque%20%3A%2A%20BMCE%20/%20BANK%20OF%20AFRICA%0A%E2%80%A2%20%2ARIB%20%3A%2A%20%60011%20780%200000402100011545%2025%60%0A%0A_Motif%20%3A%20A11%20-%20MME%20TORRES%20HIND_%0A%0AMerci%20pour%20votre%20pr%C3%A9cieuse%20collaboration.%0A%2ALe%20Bureau%20du%20Syndic%2A", "📲 Envoyer WhatsApp Direct") | Y21: 🏢 *SYNDICAT RÉSIDENCE BELLES LOGES* 📍 Rue Attabari, Quartier Les Princesses, Casablanca Bonjour *MME TORRES HIND*, Veuillez trouver ci-dessous l'appel de cotisations syndicales pour votre bien (*Appartement N°11* / A11) : 📅 *Période :* Année 2026 💰 *Total à régler :* *3600 DH* 📄 *Télécharger votre document officiel (PDF) :* 👉 https://srbl.netlify.app/pdf/appel-A11.pdf 🏦 *Coordonnées bancaires pour le virement :* • *Bénéficiaire :* SYNDICAT RESIDENCE BELLES LOGES • *Banque :* BMCE / BANK OF AFRICA • *RIB :* `011 780 0000402100011545 25` _Motif : A11 - MME TORRES HIND_ Merci pour votre précieuse collaboration. *Le Bureau du Syndic* | Z21: =HYPERLINK("https://srbl.netlify.app/?client=A11", "👤 Espace Client (A11)")
B22: ELMOSTAFA EL GUESSAB | C22: 0705262264 | D22: 45139 | F22: Appartement N°12 | G22: 900 | H22: 300 | I22: 300 | J22: 300 | K22: 300 | L22: 300 | M22: 300 | N22: 300 | O22: 300 | P22: 300 | Q22: 300 | R22: 300 | S22: =SUM(G22:R22) | T22: =-(3600-S22) | U22: ='Cotisation 2025'!U22 | V22: ='Cotisation 2025'!V22 | W22: =HYPERLINK("https://srbl.netlify.app/pdf/appel-A01.pdf", "📄 Voir PDF (A01)") | X22: =HYPERLINK("https://wa.me/212705262264?text=%F0%9F%8F%A2%20%2ASYNDICAT%20R%C3%89SIDENCE%20BELLES%20LOGES%2A%0A%F0%9F%93%8D%20Rue%20Attabari%2C%20Quartier%20Les%20Princesses%2C%20Casablanca%0A%0ABonjour%20%2AELMOSTAFA%20EL%20GUESSAB%2A%2C%0A%0AVeuillez%20trouver%20ci-dessous%20l%27appel%20de%20cotisations%20syndicales%20pour%20votre%20bien%20%28%2AAppartement%20N%C2%B012%2A%20/%20A01%29%20%3A%0A%0A%F0%9F%93%85%20%2AP%C3%A9riode%20%3A%2A%20Ann%C3%A9e%202026%0A%F0%9F%92%B0%20%2ATotal%20%C3%A0%20r%C3%A9gler%20%3A%2A%20%2A3600%20DH%2A%0A%0A%F0%9F%93%84%20%2AT%C3%A9l%C3%A9charger%20votre%20document%20officiel%20%28PDF%29%20%3A%2A%0A%F0%9F%91%89%20https%3A//srbl.netlify.app/pdf/appel-A01.pdf%0A%0A%F0%9F%8F%A6%20%2ACoordonn%C3%A9es%20bancaires%20pour%20le%20virement%20%3A%2A%0A%E2%80%A2%20%2AB%C3%A9n%C3%A9ficiaire%20%3A%2A%20SYNDICAT%20RESIDENCE%20BELLES%20LOGES%0A%E2%80%A2%20%2ABanque%20%3A%2A%20BMCE%20/%20BANK%20OF%20AFRICA%0A%E2%80%A2%20%2ARIB%20%3A%2A%20%60011%20780%200000402100011545%2025%60%0A%0A_Motif%20%3A%20A01%20-%20ELMOSTAFA%20EL%20GUESSAB_%0A%0AMerci%20pour%20votre%20pr%C3%A9cieuse%20collaboration.%0A%2ALe%20Bureau%20du%20Syndic%2A", "📲 Envoyer WhatsApp Direct") | Y22: 🏢 *SYNDICAT RÉSIDENCE BELLES LOGES* 📍 Rue Attabari, Quartier Les Princesses, Casablanca Bonjour *ELMOSTAFA EL GUESSAB*, Veuillez trouver ci-dessous l'appel de cotisations syndicales pour votre bien (*Appartement N°12* / A01) : 📅 *Période :* Année 2026 💰 *Total à régler :* *3600 DH* 📄 *Télécharger votre document officiel (PDF) :* 👉 https://srbl.netlify.app/pdf/appel-A01.pdf 🏦 *Coordonnées bancaires pour le virement :* • *Bénéficiaire :* SYNDICAT RESIDENCE BELLES LOGES • *Banque :* BMCE / BANK OF AFRICA • *RIB :* `011 780 0000402100011545 25` _Motif : A01 - ELMOSTAFA EL GUESSAB_ Merci pour votre précieuse collaboration. *Le Bureau du Syndic* | Z22: =HYPERLINK("https://srbl.netlify.app/?client=A01", "👤 Espace Client (A01)")
B23: DOUKKALI BOUALAM ZINEB / ABDELHADI NADIFI | C23: 0661214852 / 0664908843 | D23: 44881 | E23: 3 | F23: Appartement N°13 | G23: 300 | H23: 300 | I23: 300 | J23: 300 | K23: 300 | L23: 300 | M23: 300 | N23: 300 | O23: 300 | P23: 300 | Q23: 300 | R23: 300 | S23: =SUM(G23:R23) | T23: =-(3600-S23) | U23: ='Cotisation 2025'!U23 | V23: ='Cotisation 2025'!V23 | W23: =HYPERLINK("https://srbl.netlify.app/pdf/appel-A13.pdf", "📄 Voir PDF (A13)") | X23: =HYPERLINK("https://wa.me/06612148520664908843?text=%F0%9F%8F%A2%20%2ASYNDICAT%20R%C3%89SIDENCE%20BELLES%20LOGES%2A%0A%F0%9F%93%8D%20Rue%20Attabari%2C%20Quartier%20Les%20Princesses%2C%20Casablanca%0A%0ABonjour%20%2ADOUKKALI%20BOUALAM%20ZINEB%20/%20ABDELHADI%20NADIFI%2A%2C%0A%0AVeuillez%20trouver%20ci-dessous%20l%27appel%20de%20cotisations%20syndicales%20pour%20votre%20bien%20%28%2AAppartement%20N%C2%B013%2A%20/%20A13%29%20%3A%0A%0A%F0%9F%93%85%20%2AP%C3%A9riode%20%3A%2A%20Ann%C3%A9e%202026%0A%F0%9F%92%B0%20%2ATotal%20%C3%A0%20r%C3%A9gler%20%3A%2A%20%2A3600%20DH%2A%0A%0A%F0%9F%93%84%20%2AT%C3%A9l%C3%A9charger%20votre%20document%20officiel%20%28PDF%29%20%3A%2A%0A%F0%9F%91%89%20https%3A//srbl.netlify.app/pdf/appel-A13.pdf%0A%0A%F0%9F%8F%A6%20%2ACoordonn%C3%A9es%20bancaires%20pour%20le%20virement%20%3A%2A%0A%E2%80%A2%20%2AB%C3%A9n%C3%A9ficiaire%20%3A%2A%20SYNDICAT%20RESIDENCE%20BELLES%20LOGES%0A%E2%80%A2%20%2ABanque%20%3A%2A%20BMCE%20/%20BANK%20OF%20AFRICA%0A%E2%80%A2%20%2ARIB%20%3A%2A%20%60011%20780%200000402100011545%2025%60%0A%0A_Motif%20%3A%20A13%20-%20DOUKKALI%20BOUALAM%20ZINEB%20/%20ABDELHADI%20NADIFI_%0A%0AMerci%20pour%20votre%20pr%C3%A9cieuse%20collaboration.%0A%2ALe%20Bureau%20du%20Syndic%2A", "📲 Envoyer WhatsApp Direct") | Y23: 🏢 *SYNDICAT RÉSIDENCE BELLES LOGES* 📍 Rue Attabari, Quartier Les Princesses, Casablanca Bonjour *DOUKKALI BOUALAM ZINEB / ABDELHADI NADIFI*, Veuillez trouver ci-dessous l'appel de cotisations syndicales pour votre bien (*Appartement N°13* / A13) : 📅 *Période :* Année 2026 💰 *Total à régler :* *3600 DH* 📄 *Télécharger votre document officiel (PDF) :* 👉 https://srbl.netlify.app/pdf/appel-A13.pdf 🏦 *Coordonnées bancaires pour le virement :* • *Bénéficiaire :* SYNDICAT RESIDENCE BELLES LOGES • *Banque :* BMCE / BANK OF AFRICA • *RIB :* `011 780 0000402100011545 25` _Motif : A13 - DOUKKALI BOUALAM ZINEB / ABDELHADI NADIFI_ Merci pour votre précieuse collaboration. *Le Bureau du Syndic* | Z23: =HYPERLINK("https://srbl.netlify.app/?client=A13", "👤 Espace Client (A13)")
B24: GHALLAB HAMID | C24: 0661311165 / 0666422524 | D24: 44958 | F24: Appartement N°14 | G24: 300 | H24: 300 | I24: 300 | J24: 300 | K24: 300 | L24: 300 | M24: 300 | N24: 300 | O24: 300 | P24: 300 | Q24: 300 | R24: 300 | S24: =SUM(G24:R24) | T24: =-(3600-S24) | U24: ='Cotisation 2025'!U24 | V24: ='Cotisation 2025'!V24 | W24: =HYPERLINK("https://srbl.netlify.app/pdf/appel-A14.pdf", "📄 Voir PDF (A14)") | X24: =HYPERLINK("https://wa.me/06613111650666422524?text=%F0%9F%8F%A2%20%2ASYNDICAT%20R%C3%89SIDENCE%20BELLES%20LOGES%2A%0A%F0%9F%93%8D%20Rue%20Attabari%2C%20Quartier%20Les%20Princesses%2C%20Casablanca%0A%0ABonjour%20%2AGHALLAB%20HAMID%2A%2C%0A%0AVeuillez%20trouver%20ci-dessous%20l%27appel%20de%20cotisations%20syndicales%20pour%20votre%20bien%20%28%2AAppartement%20N%C2%B014%2A%20/%20A14%29%20%3A%0A%0A%F0%9F%93%85%20%2AP%C3%A9riode%20%3A%2A%20Ann%C3%A9e%202026%0A%F0%9F%92%B0%20%2ATotal%20%C3%A0%20r%C3%A9gler%20%3A%2A%20%2A3600%20DH%2A%0A%0A%F0%9F%93%84%20%2AT%C3%A9l%C3%A9charger%20votre%20document%20officiel%20%28PDF%29%20%3A%2A%0A%F0%9F%91%89%20https%3A//srbl.netlify.app/pdf/appel-A14.pdf%0A%0A%F0%9F%8F%A6%20%2ACoordonn%C3%A9es%20bancaires%20pour%20le%20virement%20%3A%2A%0A%E2%80%A2%20%2AB%C3%A9n%C3%A9ficiaire%20%3A%2A%20SYNDICAT%20RESIDENCE%20BELLES%20LOGES%0A%E2%80%A2%20%2ABanque%20%3A%2A%20BMCE%20/%20BANK%20OF%20AFRICA%0A%E2%80%A2%20%2ARIB%20%3A%2A%20%60011%20780%200000402100011545%2025%60%0A%0A_Motif%20%3A%20A14%20-%20GHALLAB%20HAMID_%0A%0AMerci%20pour%20votre%20pr%C3%A9cieuse%20collaboration.%0A%2ALe%20Bureau%20du%20Syndic%2A", "📲 Envoyer WhatsApp Direct") | Y24: 🏢 *SYNDICAT RÉSIDENCE BELLES LOGES* 📍 Rue Attabari, Quartier Les Princesses, Casablanca Bonjour *GHALLAB HAMID*, Veuillez trouver ci-dessous l'appel de cotisations syndicales pour votre bien (*Appartement N°14* / A14) : 📅 *Période :* Année 2026 💰 *Total à régler :* *3600 DH* 📄 *Télécharger votre document officiel (PDF) :* 👉 https://srbl.netlify.app/pdf/appel-A14.pdf 🏦 *Coordonnées bancaires pour le virement :* • *Bénéficiaire :* SYNDICAT RESIDENCE BELLES LOGES • *Banque :* BMCE / BANK OF AFRICA • *RIB :* `011 780 0000402100011545 25` _Motif : A14 - GHALLAB HAMID_ Merci pour votre précieuse collaboration. *Le Bureau du Syndic* | Z24: =HYPERLINK("https://srbl.netlify.app/?client=A14", "👤 Espace Client (A14)")
B25: DRISS BENNANI | C25: 0661317078 | D25: 44854 | F25: Appartement N°15 | G25: 300 | H25: 300 | I25: 300 | J25: 300 | K25: 300 | L25: 300 | M25: 300 | N25: 300 | O25: 300 | P25: 0 | Q25: 0 | R25: 0 | S25: =SUM(G25:R25) | T25: =-(3600-S25) | U25: ='Cotisation 2025'!U25 | V25: ='Cotisation 2025'!V25 | W25: =HYPERLINK("https://srbl.netlify.app/pdf/appel-A15.pdf", "📄 Voir PDF (A15)") | X25: =HYPERLINK("https://wa.me/212661317078?text=%F0%9F%8F%A2%20%2ASYNDICAT%20R%C3%89SIDENCE%20BELLES%20LOGES%2A%0A%F0%9F%93%8D%20Rue%20Attabari%2C%20Quartier%20Les%20Princesses%2C%20Casablanca%0A%0ABonjour%20%2ADRISS%20BENNANI%2A%2C%0A%0AVeuillez%20trouver%20ci-dessous%20l%27appel%20de%20cotisations%20syndicales%20pour%20votre%20bien%20%28%2AAppartement%20N%C2%B015%2A%20/%20A15%29%20%3A%0A%0A%F0%9F%93%85%20%2AP%C3%A9riode%20%3A%2A%20Ann%C3%A9e%202026%0A%F0%9F%92%B0%20%2ATotal%20%C3%A0%20r%C3%A9gler%20%3A%2A%20%2A3600%20DH%2A%0A%0A%F0%9F%93%84%20%2AT%C3%A9l%C3%A9charger%20votre%20document%20officiel%20%28PDF%29%20%3A%2A%0A%F0%9F%91%89%20https%3A//srbl.netlify.app/pdf/appel-A15.pdf%0A%0A%F0%9F%8F%A6%20%2ACoordonn%C3%A9es%20bancaires%20pour%20le%20virement%20%3A%2A%0A%E2%80%A2%20%2AB%C3%A9n%C3%A9ficiaire%20%3A%2A%20SYNDICAT%20RESIDENCE%20BELLES%20LOGES%0A%E2%80%A2%20%2ABanque%20%3A%2A%20BMCE%20/%20BANK%20OF%20AFRICA%0A%E2%80%A2%20%2ARIB%20%3A%2A%20%60011%20780%200000402100011545%2025%60%0A%0A_Motif%20%3A%20A15%20-%20DRISS%20BENNANI_%0A%0AMerci%20pour%20votre%20pr%C3%A9cieuse%20collaboration.%0A%2ALe%20Bureau%20du%20Syndic%2A", "📲 Envoyer WhatsApp Direct") | Y25: 🏢 *SYNDICAT RÉSIDENCE BELLES LOGES* 📍 Rue Attabari, Quartier Les Princesses, Casablanca Bonjour *DRISS BENNANI*, Veuillez trouver ci-dessous l'appel de cotisations syndicales pour votre bien (*Appartement N°15* / A15) : 📅 *Période :* Année 2026 💰 *Total à régler :* *3600 DH* 📄 *Télécharger votre document officiel (PDF) :* 👉 https://srbl.netlify.app/pdf/appel-A15.pdf 🏦 *Coordonnées bancaires pour le virement :* • *Bénéficiaire :* SYNDICAT RESIDENCE BELLES LOGES • *Banque :* BMCE / BANK OF AFRICA • *RIB :* `011 780 0000402100011545 25` _Motif : A15 - DRISS BENNANI_ Merci pour votre précieuse collaboration. *Le Bureau du Syndic* | Z25: =HYPERLINK("https://srbl.netlify.app/?client=A15", "👤 Espace Client (A15)")
B26: GHALLAB MOUHSSINE | C26: 0661157305 | D26: 44958 | F26: Appartement N°16 | G26: 300 | H26: 300 | I26: 300 | J26: 300 | K26: 300 | L26: 300 | M26: 300 | N26: 300 | O26: 300 | P26: 0 | Q26: 0 | R26: 0 | S26: =SUM(G26:R26) | T26: =-(3600-S26) | U26: ='Cotisation 2025'!U26 | V26: ='Cotisation 2025'!V26 | W26: =HYPERLINK("https://srbl.netlify.app/pdf/appel-A16.pdf", "📄 Voir PDF (A16)") | X26: =HYPERLINK("https://wa.me/212661157305?text=%F0%9F%8F%A2%20%2ASYNDICAT%20R%C3%89SIDENCE%20BELLES%20LOGES%2A%0A%F0%9F%93%8D%20Rue%20Attabari%2C%20Quartier%20Les%20Princesses%2C%20Casablanca%0A%0ABonjour%20%2AGHALLAB%20MOUHSSINE%2A%2C%0A%0AVeuillez%20trouver%20ci-dessous%20l%27appel%20de%20cotisations%20syndicales%20pour%20votre%20bien%20%28%2AAppartement%20N%C2%B016%2A%20/%20A16%29%20%3A%0A%0A%F0%9F%93%85%20%2AP%C3%A9riode%20%3A%2A%20Ann%C3%A9e%202026%0A%F0%9F%92%B0%20%2ATotal%20%C3%A0%20r%C3%A9gler%20%3A%2A%20%2A3600%20DH%2A%0A%0A%F0%9F%93%84%20%2AT%C3%A9l%C3%A9charger%20votre%20document%20officiel%20%28PDF%29%20%3A%2A%0A%F0%9F%91%89%20https%3A//srbl.netlify.app/pdf/appel-A16.pdf%0A%0A%F0%9F%8F%A6%20%2ACoordonn%C3%A9es%20bancaires%20pour%20le%20virement%20%3A%2A%0A%E2%80%A2%20%2AB%C3%A9n%C3%A9ficiaire%20%3A%2A%20SYNDICAT%20RESIDENCE%20BELLES%20LOGES%0A%E2%80%A2%20%2ABanque%20%3A%2A%20BMCE%20/%20BANK%20OF%20AFRICA%0A%E2%80%A2%20%2ARIB%20%3A%2A%20%60011%20780%200000402100011545%2025%60%0A%0A_Motif%20%3A%20A16%20-%20GHALLAB%20MOUHSSINE_%0A%0AMerci%20pour%20votre%20pr%C3%A9cieuse%20collaboration.%0A%2ALe%20Bureau%20du%20Syndic%2A", "📲 Envoyer WhatsApp Direct") | Y26: 🏢 *SYNDICAT RÉSIDENCE BELLES LOGES* 📍 Rue Attabari, Quartier Les Princesses, Casablanca Bonjour *GHALLAB MOUHSSINE*, Veuillez trouver ci-dessous l'appel de cotisations syndicales pour votre bien (*Appartement N°16* / A16) : 📅 *Période :* Année 2026 💰 *Total à régler :* *3600 DH* 📄 *Télécharger votre document officiel (PDF) :* 👉 https://srbl.netlify.app/pdf/appel-A16.pdf 🏦 *Coordonnées bancaires pour le virement :* • *Bénéficiaire :* SYNDICAT RESIDENCE BELLES LOGES • *Banque :* BMCE / BANK OF AFRICA • *RIB :* `011 780 0000402100011545 25` _Motif : A16 - GHALLAB MOUHSSINE_ Merci pour votre précieuse collaboration. *Le Bureau du Syndic* | Z26: =HYPERLINK("https://srbl.netlify.app/?client=A16", "👤 Espace Client (A16)") | AA26: =U40+2640
B27: GHALLAB HAMID | C27: 0661311165 / 0666422524 | D27: 44958 | F27: Appartement N°17 | G27: 300 | H27: 300 | I27: 300 | J27: 300 | K27: 300 | L27: 300 | M27: 300 | N27: 300 | O27: 300 | P27: 300 | Q27: 300 | R27: 300 | S27: =SUM(G27:R27) | T27: =-(3600-S27) | U27: ='Cotisation 2025'!U27 | V27: ='Cotisation 2025'!V27 | W27: =HYPERLINK("https://srbl.netlify.app/pdf/appel-A17.pdf", "📄 Voir PDF (A17)") | X27: =HYPERLINK("https://wa.me/06613111650666422524?text=%F0%9F%8F%A2%20%2ASYNDICAT%20R%C3%89SIDENCE%20BELLES%20LOGES%2A%0A%F0%9F%93%8D%20Rue%20Attabari%2C%20Quartier%20Les%20Princesses%2C%20Casablanca%0A%0ABonjour%20%2AGHALLAB%20HAMID%2A%2C%0A%0AVeuillez%20trouver%20ci-dessous%20l%27appel%20de%20cotisations%20syndicales%20pour%20votre%20bien%20%28%2AAppartement%20N%C2%B017%2A%20/%20A17%29%20%3A%0A%0A%F0%9F%93%85%20%2AP%C3%A9riode%20%3A%2A%20Ann%C3%A9e%202026%0A%F0%9F%92%B0%20%2ATotal%20%C3%A0%20r%C3%A9gler%20%3A%2A%20%2A3600%20DH%2A%0A%0A%F0%9F%93%84%20%2AT%C3%A9l%C3%A9charger%20votre%20document%20officiel%20%28PDF%29%20%3A%2A%0A%F0%9F%91%89%20https%3A//srbl.netlify.app/pdf/appel-A17.pdf%0A%0A%F0%9F%8F%A6%20%2ACoordonn%C3%A9es%20bancaires%20pour%20le%20virement%20%3A%2A%0A%E2%80%A2%20%2AB%C3%A9n%C3%A9ficiaire%20%3A%2A%20SYNDICAT%20RESIDENCE%20BELLES%20LOGES%0A%E2%80%A2%20%2ABanque%20%3A%2A%20BMCE%20/%20BANK%20OF%20AFRICA%0A%E2%80%A2%20%2ARIB%20%3A%2A%20%60011%20780%200000402100011545%2025%60%0A%0A_Motif%20%3A%20A17%20-%20GHALLAB%20HAMID_%0A%0AMerci%20pour%20votre%20pr%C3%A9cieuse%20collaboration.%0A%2ALe%20Bureau%20du%20Syndic%2A", "📲 Envoyer WhatsApp Direct") | Y27: 🏢 *SYNDICAT RÉSIDENCE BELLES LOGES* 📍 Rue Attabari, Quartier Les Princesses, Casablanca Bonjour *GHALLAB HAMID*, Veuillez trouver ci-dessous l'appel de cotisations syndicales pour votre bien (*Appartement N°17* / A17) : 📅 *Période :* Année 2026 💰 *Total à régler :* *3600 DH* 📄 *Télécharger votre document officiel (PDF) :* 👉 https://srbl.netlify.app/pdf/appel-A17.pdf 🏦 *Coordonnées bancaires pour le virement :* • *Bénéficiaire :* SYNDICAT RESIDENCE BELLES LOGES • *Banque :* BMCE / BANK OF AFRICA • *RIB :* `011 780 0000402100011545 25` _Motif : A17 - GHALLAB HAMID_ Merci pour votre précieuse collaboration. *Le Bureau du Syndic* | Z27: =HYPERLINK("https://srbl.netlify.app/?client=A17", "👤 Espace Client (A17)")
B28: MME BEN BRAHIM ANDALOUSSI FATTOUMA | C28: 0661324710 | D28: 45108 | F28: Appartement N°18 | G28: 300 | H28: 300 | I28: 300 | J28: 300 | K28: 300 | L28: 300 | M28: 300 | N28: 300 | O28: 300 | P28: 300 | Q28: 300 | R28: 300 | S28: =SUM(G28:R28) | T28: =-(3600-S28) | U28: ='Cotisation 2025'!U28 | V28: ='Cotisation 2025'!V28 | W28: =HYPERLINK("https://srbl.netlify.app/pdf/appel-A18.pdf", "📄 Voir PDF (A18)") | X28: =HYPERLINK("https://wa.me/212661324710?text=%F0%9F%8F%A2%20%2ASYNDICAT%20R%C3%89SIDENCE%20BELLES%20LOGES%2A%0A%F0%9F%93%8D%20Rue%20Attabari%2C%20Quartier%20Les%20Princesses%2C%20Casablanca%0A%0ABonjour%20%2AMME%20BEN%20BRAHIM%20ANDALOUSSI%20FATTOUMA%2A%2C%0A%0AVeuillez%20trouver%20ci-dessous%20l%27appel%20de%20cotisations%20syndicales%20pour%20votre%20bien%20%28%2AAppartement%20N%C2%B018%2A%20/%20A18%29%20%3A%0A%0A%F0%9F%93%85%20%2AP%C3%A9riode%20%3A%2A%20Ann%C3%A9e%202026%0A%F0%9F%92%B0%20%2ATotal%20%C3%A0%20r%C3%A9gler%20%3A%2A%20%2A3600%20DH%2A%0A%0A%F0%9F%93%84%20%2AT%C3%A9l%C3%A9charger%20votre%20document%20officiel%20%28PDF%29%20%3A%2A%0A%F0%9F%91%89%20https%3A//srbl.netlify.app/pdf/appel-A18.pdf%0A%0A%F0%9F%8F%A6%20%2ACoordonn%C3%A9es%20bancaires%20pour%20le%20virement%20%3A%2A%0A%E2%80%A2%20%2AB%C3%A9n%C3%A9ficiaire%20%3A%2A%20SYNDICAT%20RESIDENCE%20BELLES%20LOGES%0A%E2%80%A2%20%2ABanque%20%3A%2A%20BMCE%20/%20BANK%20OF%20AFRICA%0A%E2%80%A2%20%2ARIB%20%3A%2A%20%60011%20780%200000402100011545%2025%60%0A%0A_Motif%20%3A%20A18%20-%20MME%20BEN%20BRAHIM%20ANDALOUSSI%20FATTOUMA_%0A%0AMerci%20pour%20votre%20pr%C3%A9cieuse%20collaboration.%0A%2ALe%20Bureau%20du%20Syndic%2A", "📲 Envoyer WhatsApp Direct") | Y28: 🏢 *SYNDICAT RÉSIDENCE BELLES LOGES* 📍 Rue Attabari, Quartier Les Princesses, Casablanca Bonjour *MME BEN BRAHIM ANDALOUSSI FATTOUMA*, Veuillez trouver ci-dessous l'appel de cotisations syndicales pour votre bien (*Appartement N°18* / A18) : 📅 *Période :* Année 2026 💰 *Total à régler :* *3600 DH* 📄 *Télécharger votre document officiel (PDF) :* 👉 https://srbl.netlify.app/pdf/appel-A18.pdf 🏦 *Coordonnées bancaires pour le virement :* • *Bénéficiaire :* SYNDICAT RESIDENCE BELLES LOGES • *Banque :* BMCE / BANK OF AFRICA • *RIB :* `011 780 0000402100011545 25` _Motif : A18 - MME BEN BRAHIM ANDALOUSSI FATTOUMA_ Merci pour votre précieuse collaboration. *Le Bureau du Syndic* | Z28: =HYPERLINK("https://srbl.netlify.app/?client=A18", "👤 Espace Client (A18)")
B29: GHALLAB MOUHSSINE | C29: 0661157305 | D29: 44958 | E29: 4 | F29: Appartement N°19 | G29: 300 | H29: 300 | I29: 300 | J29: 300 | K29: 300 | L29: 300 | M29: 300 | N29: 300 | O29: 300 | P29: 0 | Q29: 0 | R29: 0 | S29: =SUM(G29:R29) | T29: =-(3600-S29) | U29: ='Cotisation 2025'!U29 | V29: ='Cotisation 2025'!V29 | W29: =HYPERLINK("https://srbl.netlify.app/pdf/appel-A19.pdf", "📄 Voir PDF (A19)") | X29: =HYPERLINK("https://wa.me/212661157305?text=%F0%9F%8F%A2%20%2ASYNDICAT%20R%C3%89SIDENCE%20BELLES%20LOGES%2A%0A%F0%9F%93%8D%20Rue%20Attabari%2C%20Quartier%20Les%20Princesses%2C%20Casablanca%0A%0ABonjour%20%2AGHALLAB%20MOUHSSINE%2A%2C%0A%0AVeuillez%20trouver%20ci-dessous%20l%27appel%20de%20cotisations%20syndicales%20pour%20votre%20bien%20%28%2AAppartement%20N%C2%B019%2A%20/%20A19%29%20%3A%0A%0A%F0%9F%93%85%20%2AP%C3%A9riode%20%3A%2A%20Ann%C3%A9e%202026%0A%F0%9F%92%B0%20%2ATotal%20%C3%A0%20r%C3%A9gler%20%3A%2A%20%2A3600%20DH%2A%0A%0A%F0%9F%93%84%20%2AT%C3%A9l%C3%A9charger%20votre%20document%20officiel%20%28PDF%29%20%3A%2A%0A%F0%9F%91%89%20https%3A//srbl.netlify.app/pdf/appel-A19.pdf%0A%0A%F0%9F%8F%A6%20%2ACoordonn%C3%A9es%20bancaires%20pour%20le%20virement%20%3A%2A%0A%E2%80%A2%20%2AB%C3%A9n%C3%A9ficiaire%20%3A%2A%20SYNDICAT%20RESIDENCE%20BELLES%20LOGES%0A%E2%80%A2%20%2ABanque%20%3A%2A%20BMCE%20/%20BANK%20OF%20AFRICA%0A%E2%80%A2%20%2ARIB%20%3A%2A%20%60011%20780%200000402100011545%2025%60%0A%0A_Motif%20%3A%20A19%20-%20GHALLAB%20MOUHSSINE_%0A%0AMerci%20pour%20votre%20pr%C3%A9cieuse%20collaboration.%0A%2ALe%20Bureau%20du%20Syndic%2A", "📲 Envoyer WhatsApp Direct") | Y29: 🏢 *SYNDICAT RÉSIDENCE BELLES LOGES* 📍 Rue Attabari, Quartier Les Princesses, Casablanca Bonjour *GHALLAB MOUHSSINE*, Veuillez trouver ci-dessous l'appel de cotisations syndicales pour votre bien (*Appartement N°19* / A19) : 📅 *Période :* Année 2026 💰 *Total à régler :* *3600 DH* 📄 *Télécharger votre document officiel (PDF) :* 👉 https://srbl.netlify.app/pdf/appel-A19.pdf 🏦 *Coordonnées bancaires pour le virement :* • *Bénéficiaire :* SYNDICAT RESIDENCE BELLES LOGES • *Banque :* BMCE / BANK OF AFRICA • *RIB :* `011 780 0000402100011545 25` _Motif : A19 - GHALLAB MOUHSSINE_ Merci pour votre précieuse collaboration. *Le Bureau du Syndic* | Z29: =HYPERLINK("https://srbl.netlify.app/?client=A19", "👤 Espace Client (A19)")
B30: GHALLAB MOUHSSINE | C30: 0661157305 | D30: 44886 | F30: Appartement N°20 | G30: 300 | H30: 300 | I30: 300 | J30: 300 | K30: 300 | L30: 300 | M30: 300 | N30: 300 | O30: 300 | P30: 300 | Q30: 300 | R30: 300 | S30: =SUM(G30:R30) | T30: =-(3600-S30) | U30: ='Cotisation 2025'!U30 | V30: ='Cotisation 2025'!V30 | W30: =HYPERLINK("https://srbl.netlify.app/pdf/appel-A02.pdf", "📄 Voir PDF (A02)") | X30: =HYPERLINK("https://wa.me/212661157305?text=%F0%9F%8F%A2%20%2ASYNDICAT%20R%C3%89SIDENCE%20BELLES%20LOGES%2A%0A%F0%9F%93%8D%20Rue%20Attabari%2C%20Quartier%20Les%20Princesses%2C%20Casablanca%0A%0ABonjour%20%2AGHALLAB%20MOUHSSINE%2A%2C%0A%0AVeuillez%20trouver%20ci-dessous%20l%27appel%20de%20cotisations%20syndicales%20pour%20votre%20bien%20%28%2AAppartement%20N%C2%B020%2A%20/%20A02%29%20%3A%0A%0A%F0%9F%93%85%20%2AP%C3%A9riode%20%3A%2A%20Ann%C3%A9e%202026%0A%F0%9F%92%B0%20%2ATotal%20%C3%A0%20r%C3%A9gler%20%3A%2A%20%2A3600%20DH%2A%0A%0A%F0%9F%93%84%20%2AT%C3%A9l%C3%A9charger%20votre%20document%20officiel%20%28PDF%29%20%3A%2A%0A%F0%9F%91%89%20https%3A//srbl.netlify.app/pdf/appel-A02.pdf%0A%0A%F0%9F%8F%A6%20%2ACoordonn%C3%A9es%20bancaires%20pour%20le%20virement%20%3A%2A%0A%E2%80%A2%20%2AB%C3%A9n%C3%A9ficiaire%20%3A%2A%20SYNDICAT%20RESIDENCE%20BELLES%20LOGES%0A%E2%80%A2%20%2ABanque%20%3A%2A%20BMCE%20/%20BANK%20OF%20AFRICA%0A%E2%80%A2%20%2ARIB%20%3A%2A%20%60011%20780%200000402100011545%2025%60%0A%0A_Motif%20%3A%20A02%20-%20GHALLAB%20MOUHSSINE_%0A%0AMerci%20pour%20votre%20pr%C3%A9cieuse%20collaboration.%0A%2ALe%20Bureau%20du%20Syndic%2A", "📲 Envoyer WhatsApp Direct") | Y30: 🏢 *SYNDICAT RÉSIDENCE BELLES LOGES* 📍 Rue Attabari, Quartier Les Princesses, Casablanca Bonjour *GHALLAB MOUHSSINE*, Veuillez trouver ci-dessous l'appel de cotisations syndicales pour votre bien (*Appartement N°20* / A02) : 📅 *Période :* Année 2026 💰 *Total à régler :* *3600 DH* 📄 *Télécharger votre document officiel (PDF) :* 👉 https://srbl.netlify.app/pdf/appel-A02.pdf 🏦 *Coordonnées bancaires pour le virement :* • *Bénéficiaire :* SYNDICAT RESIDENCE BELLES LOGES • *Banque :* BMCE / BANK OF AFRICA • *RIB :* `011 780 0000402100011545 25` _Motif : A02 - GHALLAB MOUHSSINE_ Merci pour votre précieuse collaboration. *Le Bureau du Syndic* | Z30: =HYPERLINK("https://srbl.netlify.app/?client=A02", "👤 Espace Client (A02)")
B31: MME BEN BRAHIM ANDALOUSSI FATTOUMA | C31: 0661324710 | D31: 44851 | F31: Appartement N°21 | G31: 300 | H31: 300 | I31: 300 | J31: 300 | K31: 300 | L31: 300 | M31: 300 | N31: 300 | O31: 300 | P31: 300 | Q31: 300 | R31: 300 | S31: =SUM(G31:R31) | T31: =-(3600-S31) | U31: ='Cotisation 2025'!U31 | V31: ='Cotisation 2025'!V31 | W31: =HYPERLINK("https://srbl.netlify.app/pdf/appel-A02.pdf", "📄 Voir PDF (A02)") | X31: =HYPERLINK("https://wa.me/212661324710?text=%F0%9F%8F%A2%20%2ASYNDICAT%20R%C3%89SIDENCE%20BELLES%20LOGES%2A%0A%F0%9F%93%8D%20Rue%20Attabari%2C%20Quartier%20Les%20Princesses%2C%20Casablanca%0A%0ABonjour%20%2AMME%20BEN%20BRAHIM%20ANDALOUSSI%20FATTOUMA%2A%2C%0A%0AVeuillez%20trouver%20ci-dessous%20l%27appel%20de%20cotisations%20syndicales%20pour%20votre%20bien%20%28%2AAppartement%20N%C2%B021%2A%20/%20A02%29%20%3A%0A%0A%F0%9F%93%85%20%2AP%C3%A9riode%20%3A%2A%20Ann%C3%A9e%202026%0A%F0%9F%92%B0%20%2ATotal%20%C3%A0%20r%C3%A9gler%20%3A%2A%20%2A3600%20DH%2A%0A%0A%F0%9F%93%84%20%2AT%C3%A9l%C3%A9charger%20votre%20document%20officiel%20%28PDF%29%20%3A%2A%0A%F0%9F%91%89%20https%3A//srbl.netlify.app/pdf/appel-A02.pdf%0A%0A%F0%9F%8F%A6%20%2ACoordonn%C3%A9es%20bancaires%20pour%20le%20virement%20%3A%2A%0A%E2%80%A2%20%2AB%C3%A9n%C3%A9ficiaire%20%3A%2A%20SYNDICAT%20RESIDENCE%20BELLES%20LOGES%0A%E2%80%A2%20%2ABanque%20%3A%2A%20BMCE%20/%20BANK%20OF%20AFRICA%0A%E2%80%A2%20%2ARIB%20%3A%2A%20%60011%20780%200000402100011545%2025%60%0A%0A_Motif%20%3A%20A02%20-%20MME%20BEN%20BRAHIM%20ANDALOUSSI%20FATTOUMA_%0A%0AMerci%20pour%20votre%20pr%C3%A9cieuse%20collaboration.%0A%2ALe%20Bureau%20du%20Syndic%2A", "📲 Envoyer WhatsApp Direct") | Y31: 🏢 *SYNDICAT RÉSIDENCE BELLES LOGES* 📍 Rue Attabari, Quartier Les Princesses, Casablanca Bonjour *MME BEN BRAHIM ANDALOUSSI FATTOUMA*, Veuillez trouver ci-dessous l'appel de cotisations syndicales pour votre bien (*Appartement N°21* / A02) : 📅 *Période :* Année 2026 💰 *Total à régler :* *3600 DH* 📄 *Télécharger votre document officiel (PDF) :* 👉 https://srbl.netlify.app/pdf/appel-A02.pdf 🏦 *Coordonnées bancaires pour le virement :* • *Bénéficiaire :* SYNDICAT RESIDENCE BELLES LOGES • *Banque :* BMCE / BANK OF AFRICA • *RIB :* `011 780 0000402100011545 25` _Motif : A02 - MME BEN BRAHIM ANDALOUSSI FATTOUMA_ Merci pour votre précieuse collaboration. *Le Bureau du Syndic* | Z31: =HYPERLINK("https://srbl.netlify.app/?client=A02", "👤 Espace Client (A02)")
